2025-03-12 10:59:40,290 - ERROR - 批次 0 處理失敗: autocast.__init__() got multiple values for argument 'enabled'
2025-03-12 10:59:40,290 - WARNING - 嘗試從錯誤中恢復: autocast.__init__() got multiple values for argument 'enabled'
2025-03-12 10:59:41,769 - ERROR - Epoch 1 執行失敗: 訓練週期失敗: autocast.__init__() got multiple values for argument 'enabled'
2025-03-12 10:59:41,770 - WARNING - 嘗試從錯誤中恢復: 訓練週期失敗: autocast.__init__() got multiple values for argument 'enabled'
2025-03-12 10:59:41,770 - ERROR - 訓練過程失敗: 訓練週期失敗: autocast.__init__() got multiple values for argument 'enabled'
2025-03-12 10:59:41,771 - ERROR - 程序執行失敗: 訓練失敗: 訓練週期失敗: autocast.__init__() got multiple values for argument 'enabled'
2025-03-12 10:59:41,772 - ERROR - 堆疊追踪:
Traceback (most recent call last):
  File "D:\project\.HomeWorkProject\bigmodel\bbb\train.py", line 129, in train_epoch
    with autocast(self.autocast_device, enabled=self.config.mixed_precision):
  File "c:\Users\daniel\anaconda3\envs\mymodel1\lib\site-packages\typing_extensions.py", line 2853, in wrapper
    return arg(*args, **kwargs)
TypeError: autocast.__init__() got multiple values for argument 'enabled'

During handling of the above exception, another exception occurred:

Traceback (most recent call last):
  File "D:\project\.HomeWorkProject\bigmodel\bbb\train.py", line 260, in train
    train_loss = self.train_epoch()
  File "D:\project\.HomeWorkProject\bigmodel\bbb\train.py", line 154, in train_epoch
    raise TrainingError(f"訓練週期失敗: {str(e)}")
utils.TrainingError: 訓練週期失敗: autocast.__init__() got multiple values for argument 'enabled'

During handling of the above exception, another exception occurred:

Traceback (most recent call last):
  File "D:\project\.HomeWorkProject\bigmodel\bbb\main.py", line 69, in main
    engine.train()
  File "D:\project\.HomeWorkProject\bigmodel\bbb\train.py", line 325, in train
    raise TrainingError(f"訓練失敗: {str(e)}")
utils.TrainingError: 訓練失敗: 訓練週期失敗: autocast.__init__() got multiple values for argument 'enabled'
